Workbook
Name Home: 'Neonatal deaths'!$A$1
Name Navigation_A1: 'Perinatal Deaths'!$A$1
Name START: Welcome!$S$13

Sheet Welcome

Sheet Navigation
P8: Number | R8: Rate | U8: Number | W8: Rate
O9: Total births | P9: ='Annual log'!AC11 -> 8337 | T9: Total births | U9: ='Annual log'!AB11 -> 3217
O11: Livebirths | P11: ='Annual log'!AC17 -> 8159 | T11: Livebirths | U11: ='Annual log'!AB17 -> 3151
O13: iPMR | P13: ='Annual log'!AC26+'Annual log'!AC14 -> 258 | R13: =Indicators!C5 -> 30.946384 | T13: iPMR | U13: ='Annual log'!AB26+'Annual log'!AB14 -> 107 | W13: =Indicators!P5 -> 33.260802
O15: iNMR | P15: ='Annual log'!AC25 -> 119 | R15: =Indicators!C6 -> 14.585121 | T15: iNMR | U15: ='Annual log'!AB25 -> 49 | W15: =Indicators!P6 -> 15.550619
O17: iSBR | P17: ='Annual log'!AC14 -> 163 | R17: =Indicators!C2 -> 19.551397 | T17: iSBR | U17: ='Annual log'!AB14 -> 66 | W17: =Indicators!P2 -> 20.516009
O19: iMMR | P19: =Indicators!C15 -> 20 | R19: =Indicators!C7 -> 245.12808 | T19: iMMR | U19: =Indicators!P15 -> 4 | W19: =Indicators!P7 -> 126.94383
O24: Recommendations made | Q24: =COUNT(Recommendations!A:A) -> 20
O26: Recommendations completed | Q26: =COUNTIFS(Recommendations!H3:H249,"=completed",Recommendations!H3:H249,"?*") -> 13 | R26: =Q26/Q24 -> 0.65

Sheet Recommendations
A1: Home | B1: Date entered | C1: Recommendation | D1: Expected date of completion | E1: Date of status review | F1: Person responsible for implementing in facility | G1: Person responsible for follow-up and reporting to team | H1: Status of implementation | I1: Comment
A2: Example (enter serial number) | B2: 43590 | C2: We recommend that the matron in-charge of the maternity unit should develop a standard operating procedure document for identifying infections in pregnancy to be used by nurses at the ANC clinics within 2 weeks from this day (5th of May, 2019). To carry out this recommendation, she/he will need support from the HOD of the Obstetrics unit for technical input and review and support for printing and the Secretary of this PDSR team will follow-up on this recommendation for the team | D2: 43604 | E2: =IF($C2="","Review Date",TODAY()) -> 44092 | F2: Matron in charge of maternity | G2: Secretary - Mr Caramansa | H2: Completed | I2: SOP was developed and curretly in print with the Ministry's printers to be delivered to the facility in a week
A3: 1 | B3: 43658 | C3: We recommend that all health care providers who see newborn babies considered as high risk (sick, low APGAR<7/5, LBW/premature, RDS, bad obstetrics history in index pregnancy, etc.) at all points of care (including theatre, labour ward, casualty, female ward, etc.) should immediately refer them for admission to the Prem Unit within 1 week starting today the 3rd of June 2019. Matron in charge of maternity and neonatal unit should ensure this is complied with. Neonatal in-charge will report to this team. | D3: 43626 | E3: =IF($C3="","Review Date",TODAY()) -> 44092 | F3: Matron in charge of maternity and Neonatal Unit | G3: Neonatal sister incharge(Sr Ndepavali) | H3: Completed | I3: All high risk newborn are admitted in prem unit
A4: 2 | B4: =IF($A4<>"", TODAY(), "") -> 44092 | C4: The CMO must ensure that the HOD of gynae/obstetric present to the committee (MPNDSR) a protocol on fluid resuscitation for patient in shock during the antepartum, intrapartum and postpartum admited in Rundu Hospital within two weeks from today (18/07/2019). | D4: 43664 | E4: =IF($C4="","Review Date",TODAY()) -> 44092 | F4: CMO | G4: Obs/Gynae HOD | H4: Completed
A5: 3 | B5: 25/07/2019 | C5: The HOD of Obs/Gynae to print out approved protocol and distribute to all wards admitting mothers in shock which should be used by all health care provider from 25/07/2019 and the sister in charge should ensure the availability of the protocol and it is being used by the Health care workers. | D5: 22/08/2019 | E5: =IF($C5="","Review Date",TODAY()) -> 44092 | F5: HOD of Obs/Gynae | G5: Matron in charge of Secialized services | H5: Completed
A6: 4 | B6: 25/07/2019 | C6: The CMO must call an urgent meeting by 12/08/2019 with all the CMOs /Mos of Rundu hospital on reinforcement of interdepartmental consultation and application of focus postnatal care (hospitalization guidelines for mothers). A mother who has non-obstetric condition should be seen by a medical Doctor from appropriate department for proper evaluation and management. | D6: 12/08/2019 | E6: =IF($C6="","Review Date",TODAY()) -> 44092 | F6: CMO | G6: CMO | H6: Completed
A7: 5 | B7: 43798 | C7: The matron in charge of prem unit should provide an orientation for the unit staff on patient monitoring, interpretation of findings and actions to be taken in case of adverse findings. This should include ensuring that Drs who review such cases address all adverse findings found. the matron will require support from peadiatric specialist to facilitate this. | D7: 43805 | E7: =IF($C7="","Review Date",TODAY()) -> 44092 | F7: Matron inchargeof Prem unit, Dr Kamara | G7: Matron in charge of Specialized services | H7: Completed
A8: 6 | B8: 43798 | C8: All Health care providers attending to/admitting new born babies should provide a complete summary of all maternal record history (ANC passport, care in labour etc) and complete all maternal records from ANC through to delivery. | D8: 05/02/2020 | E8: =IF($C8="","Review Date",TODAY()) -> 44092 | F8: Prem unit In charge | G8: Matron in charge of Specialized services | H8: Completed | I8: The activity
A9: 7 | B9: 28/11/2019 | C9: We recommend that all Doctors who admit or review babies in the prem unit should provide a clear care plans for the patient, write them down and communicate to the nurses. | D9: 05/02/2020 | E9: =IF($C9="","Review Date",TODAY()) -> 44092 | F9: Matron inchargeof Prem unit, Dr Kamara | G9: Matron in charge of Specialized services | H9: Completed
A10: 9 | B10: 05/12/2019 | C10: we recommend that all health workers attending to a fresh still birth deliveries in the labor ward and theatre must attempt resuscitation before declaring dead and and documenting. | D10: 06/12/2019 | E10: =IF($C10="","Review Date",TODAY()) -> 44092 | F10: Maternity Ward Incharge | G10: Quality Control (Sr Shautama) | H10: Completed
A11: 10 | B11: 05/12/2019 | C11: We recommend that Health Care Workers in the maternity ward discharging mothers with babies , should ensure to give mothers health education on seeking early medical intentions, avoid using traditional medicines at home and it's dangers to babies. This should be documented in the maternity record and ward health education book. | D11: 06/12/2019 | E11: =IF($C11="","Review Date",TODAY()) -> 44092 | F11: Maternity Ward Incharge | G11: Inchargeof Prem unit | H11: Completed
A12: 11 | B12: 19/12/2019 | C12: We recommend that the protocol should be developed on how to manage pregnant women presenting with difficulty in breathingin maternity ward, | D12: 15/01/2020 | E12: =IF($C12="","Review Date",TODAY()) -> 44092 | F12: Obs/Gynae SMO | G12: Maternity Ward Incharge | H12: PENDING
A13: 12 | B13: 19/12/2019 | C13: We recommend that orientation on developed protocol should be done to all maternity staffs (Nurses and Doctors)on handling women presenting with diffificulty in breathing. | D13: 23/01/2020 | E13: =IF($C13="","Review Date",TODAY()) -> 44092 | F13: Inservice Trainning Personnel | G13: Sr Haikera | H13: PENDING
A14: 13 | B14: 19/12/2019 | C14: Good practice noted of perimortem caessarian section done on a collapsed pregnant woman where two lives of newborn babies compared to one death of a mother. | E14: =IF($C14="","Review Date",TODAY()) -> 44092 | H14: Completed
A15: 14 | B15: 28/11/2019 | C15: We recommend that all midwifes attending to mothers who delivered stillborn, to make a copy on an antenatal health passport before discharging or upon death registration. | D15: 05/12/2019 | E15: =IF($C15="","Review Date",TODAY()) -> 44092 | F15: Maternity Ward Incharge | G15: Sr Haikera | H15: Completed | I15: challenges with logistic to make copies of the file
A16: 15 | B16: 28/11/2019 | C16: We recommend that midwifes examining mothers and have doubt with fetal heart rate by CTG, should confirm FHR by comparing with a maternal pulse. | D16: 02/12/2019 | E16: =IF($C16="","Review Date",TODAY()) -> 44092 | F16: Maternity Ward Incharge | G16: Sr Haikera | H16: Completed | I16: difficult to verify
A17: 16 | B17: 43950 | C17: We recommend that maternity ward incharge to strengthen universal and complete use of partogram for every patient in active phase of labour by reviewing partograms on a daily basis. This eill help early detection on lapsis of using partogram. | D17: 14/05/2020 | E17: =IF($C17="","Review Date",TODAY()) -> 44092 | F17: Dr Oyedele & Sr Shoopala | G17: Sr Shoopala | H17: Completed | I17: The activity is ongoing
A18: 17 | B18: 43950 | C18: We recommend that peaditric specialist need to develop a protocol on management of neonatal patients requiring respiratory support. | D18: 43993 | E18: =IF($C18="","Review Date",TODAY()) -> 44092 | F18: Dr Kamara | G18: Sr Ndepavali
A19: 18 | B19: 43958 | C19: We recommend that peaditric specialist should train all midwives in maternity ward on neonatal resuscitation to ensure that early resuscitation is attempted in all neonates born in distress. | D19: 44019 | E19: =IF($C19="","Review Date",TODAY()) -> 44092 | F19: Dr Kamara | G19: Sr Shopala
A20: 19 | B20: 07/05//2020 | C20: We recommend that maternity ward incharge should ensure that all mothers are given health education which includes dangers of using traditional medicine on new born babies and importance of seeking medical care early. This will be monitored by checking on the record for health education given to post natal mothers | D20: 43993 | E20: =IF($C20="","Review Date",TODAY()) -> 44092 | F20: Sr Shopala | G20: Sr Haikera
A21: 20 | B21: 43958 | C21: We recommend that maternity ward incharge should ensure that the admitting midwifes are probing more on the reason the mother presents late (second stage of labour) to the hospital and if there is anything they may have taken at home to facilitate labour and educate them accordingly. this will help with documentation and research purpose on stillbirths. | D21: 43993 | E21: =IF($C21="","Review Date",TODAY()) -> 44092 | F21: Sr Shopala | G21: Sr Haikera
A22: 21 | B22: =IF($A22<>"", TODAY(), "") -> 44092 | C22: We recommend that SMO Obs/Gynae to formulate and issue a standing order that requires all mothers who deliver stillborn babies to be discharged only after they have been reviewed by medical social workers for psychosocial support services. | D22: 11/06/2020 | E22: =IF($C22="","Review Date",TODAY()) -> 44092 | F22: Dr Luboya | G22: Sr Shopala
B24: =IF($A24<>"", TODAY(), "") | E24: =IF($C24="","Review Date",TODAY()) -> Review Date
B25: =IF($A25<>"", TODAY(), "") | E25: =IF($C25="","Review Date",TODAY()) -> Review Date
B26: =IF($A26<>"", TODAY(), "") | E26: =IF($C26="","Review Date",TODAY()) -> Review Date
B27: =IF($A27<>"", TODAY(), "") | E27: =IF($C27="","Review Date",TODAY()) -> Review Date
B28: =IF($A28<>"", TODAY(), "") | E28: =IF($C28="","Review Date",TODAY()) -> Review Date
B29: =IF($A29<>"", TODAY(), "") | E29: =IF($C29="","Review Date",TODAY()) -> Review Date
B30: =IF($A30<>"", TODAY(), "") | E30: =IF($C30="","Review Date",TODAY()) -> Review Date
B31: =IF($A31<>"", TODAY(), "") | E31: =IF($C31="","Review Date",TODAY()) -> Review Date
B32: =IF($A32<>"", TODAY(), "") | E32: =IF($C32="","Review Date",TODAY()) -> Review Date
B33: =IF($A33<>"", TODAY(), "") | E33: =IF($C33="","Review Date",TODAY()) -> Review Date
B34: =IF($A34<>"", TODAY(), "") | E34: =IF($C34="","Review Date",TODAY()) -> Review Date
B35: =IF($A35<>"", TODAY(), "") | E35: =IF($C35="","Review Date",TODAY()) -> Review Date
... B120: =IF($A120<>"", TODAY(), "") | E120: =IF($C120="","Review Date",TODAY()) -> Review Date

Sheet Annual log
A1: Name of facility:
A2: Town
A3: District
A4: Province/Region
A5: Country
A6: Year= | B6: Month/Statistic | C6: Jan | D6: Feb | E6: Mar | F6: Apr | G6: May | H6: Jun | I6: Jul | J6: Aug | K6: Sep | L6: Oct | M6: Nov | N6: Dec | O6: Total2019 | P6: 43831 | Q6: 43862 | R6: 43891 | S6: 43922 | T6: 43952 | U6: 43983 | V6: 44013 | W6: 44044 | X6: 44075 | Y6: 44105 | Z6: 44136 | AA6: 44166 | AB6: Total2020 | AC6: Overall total
B7: Total Deliveries | C7: =SUM(Jan!C2:G2) -> 452 | D7: =SUM(Feb!C2:G2) -> 377 | E7: =SUM(Mar!C2:G2) -> 445 | F7: =SUM(Apr!C2:G2) -> 411 | G7: =SUM(May!C2:G2) -> 464 | H7: =SUM(Jun!C2:G2) -> 428 | I7: =SUM(Jul!C2:G2) -> 428 | J7: =SUM(Aug!C2:G2) -> 391 | K7: =SUM(Sep!C2:G2) -> 467 | L7: =SUM(Oct!C2:G2) -> 398 | M7: =SUM(Nov!C2:G2) -> 383 | N7: =SUM(Dec!C2:G2) -> 413 | O7: =SUM(C7:N7) -> 5057 | P7: =SUM('Jan20'!C2:G2) -> 462 | Q7: =SUM('Feb20'!C2:G2) -> 499 | R7: =SUM('Mar20'!C2:G2) -> 509 | S7: =SUM('Apr20'!C2:G2) -> 540 | T7: =SUM('May20'!C2:G2) -> 598 | U7: =SUM('Jun20'!C2:G2) -> 571 | V7: =SUM('Jul20'!C2:G2) -> 0 | W7: =SUM('Aug20'!C2:G2) -> 0 | X7: =SUM('Sep20'!C2:G2) -> 0 | Y7: =SUM('Oct20'!C2:G2) -> 0 | Z7: =SUM('Nov20'!C2:G2) -> 0 | AA7: =SUM('Dec20'!C2:G2) -> 0 | AB7: =SUM(P7:AA7) -> 3179 | AC7: =O7+AB7 -> 8236
B8: SVDs/NVDs | C8: =SUM(Jan!C3:G3) -> 368 | D8: =SUM(Feb!C3:G3) -> 313 | E8: =SUM(Mar!C3:G3) -> 357 | F8: =SUM(Apr!C3:G3) -> 321 | G8: =SUM(May!C3:G3) -> 376 | H8: =SUM(Jun!C3:G3) -> 352 | I8: =SUM(Jul!C3:G3) -> 342 | J8: =SUM(Aug!C3:G3) -> 318 | K8: =SUM(Sep!C3:G3) -> 390 | L8: =SUM(Oct!C3:G3) -> 339 | M8: =SUM(Nov!C3:G3) -> 310 | N8: =SUM(Dec!C3:G3) -> 339 | O8: =SUM(C8:N8) -> 4125 | P8: =SUM('Jan20'!C3:G3) -> 393 | Q8: =SUM('Feb20'!C3:G3) -> 418 | R8: =SUM('Mar20'!C3:G3) -> 433 | S8: =SUM('Apr20'!C3:G3) -> 447 | T8: =SUM('May20'!C3:G3) -> 488 | U8: =SUM('Jun20'!C3:G3) -> 469 | V8: =SUM('Jul20'!C3:G3) -> 0 | W8: =SUM('Aug20'!C3:G3) -> 0 | X8: =SUM('Sep20'!C3:G3) -> 0 | Y8: =SUM('Oct20'!C3:G3) -> 0 | Z8: =SUM('Nov20'!C3:G3) -> 0 | AA8: =SUM('Dec20'!C3:G3) -> 0 | AB8: =SUM(P8:AA8) -> 2648 | AC8: =O8+AB8 -> 6773
B9: Assisted | C9: =SUM(Jan!C4:G4) -> 1 | D9: =SUM(Feb!C4:G4) -> 6 | E9: =SUM(Mar!C4:G4) -> 1 | F9: =SUM(Apr!C4:G4) -> 8 | G9: =SUM(May!C4:G4) -> 4 | H9: =SUM(Jun!C4:G4) -> 2 | I9: =SUM(Jul!C4:G4) -> 7 | J9: =SUM(Aug!C4:G4) -> 4 | K9: =SUM(Sep!C4:G4) -> 4 | L9: =SUM(Oct!C4:G4) -> 3 | M9: =SUM(Nov!C4:G4) -> 5 | N9: =SUM(Dec!C4:G4) -> 0 | O9: =SUM(C9:N9) -> 45 | P9: =SUM('Jan20'!C4:G4) -> 1 | Q9: =SUM('Feb20'!C4:G4) -> 8 | R9: =SUM('Mar20'!C4:G4) -> 2 | S9: =SUM('Apr20'!C4:G4) -> 13 | T9: =SUM('May20'!C4:G4) -> 15 | U9: =SUM('Jun20'!C4:G4) -> 6 | V9: =SUM('Jul20'!C4:G4) -> 0 | W9: =SUM('Aug20'!C4:G4) -> 0 | X9: =SUM('Sep20'!C4:G4) -> 0 | Y9: =SUM('Oct20'!C4:G4) -> 0 | Z9: =SUM('Nov20'!C4:G4) -> 0 | AA9: =SUM('Dec20'!C4:G4) -> 0 | AB9: =SUM(P9:AA9) -> 45 | AC9: =O9+AB9 -> 90
B10: Caesarean Sections | C10: =SUM(Jan!C5:G5) -> 83 | D10: =SUM(Feb!C5:G5) -> 58 | E10: =SUM(Mar!C5:G5) -> 87 | F10: =SUM(Apr!C5:G5) -> 82 | G10: =SUM(May!C5:G5) -> 84 | H10: =SUM(Jun!C5:G5) -> 74 | I10: =SUM(Jul!C5:G5) -> 79 | J10: =SUM(Aug!C5:G5) -> 69 | K10: =SUM(Sep!C5:G5) -> 73 | L10: =SUM(Oct!C5:G5) -> 56 | M10: =SUM(Nov!C5:G5) -> 68 | N10: =SUM(Dec!C5:G5) -> 74 | O10: =SUM(C10:N10) -> 887 | P10: =SUM('Jan20'!C5:G5) -> 68 | Q10: =SUM('Feb20'!C5:G5) -> 73 | R10: =SUM('Mar20'!C5:G5) -> 74 | S10: =SUM('Apr20'!C5:G5) -> 80 | T10: =SUM('May20'!C5:G5) -> 95 | U10: =SUM('Jun20'!C5:G5) -> 96 | V10: =SUM('Jul20'!C5:G5) -> 0 | W10: =SUM('Aug20'!C5:G5) -> 0 | X10: =SUM('Sep20'!C5:G5) -> 0 | Y10: =SUM('Oct20'!C5:G5) -> 0 | Z10: =SUM('Nov20'!C5:G5) -> 0 | AA10: =SUM('Dec20'!C5:G5) -> 0 | AB10: =SUM(P10:AA10) -> 486 | AC10: =O10+AB10 -> 1373
B11: Total Births | C11: =SUM(Jan!C6:G6) -> 447 | D11: =SUM(Feb!C6:G6) -> 384 | E11: =SUM(Mar!C6:G6) -> 450 | F11: =SUM(Apr!C6:G6) -> 420 | G11: =SUM(May!C6:G6) -> 470 | H11: =SUM(Jun!C6:G6) -> 430 | I11: =SUM(Jul!C6:G6) -> 434 | J11: =SUM(Aug!C6:G6) -> 390 | K11: =SUM(Sep!C6:G6) -> 471 | L11: =SUM(Oct!C6:G6) -> 404 | M11: =SUM(Nov!C6:G6) -> 388 | N11: =SUM(Dec!C6:G6) -> 432 | O11: =SUM(C11:N11) -> 5120 | P11: =SUM('Jan20'!C6:G6) -> 462 | Q11: =SUM('Feb20'!C6:G6) -> 514 | R11: =SUM('Mar20'!C6:G6) -> 512 | S11: =SUM('Apr20'!C6:G6) -> 546 | T11: =SUM('May20'!C6:G6) -> 603 | U11: =SUM('Jun20'!C6:G6) -> 580 | V11: =SUM('Jul20'!C6:G6) -> 0 | W11: =SUM('Aug20'!C6:G6) -> 0 | X11: =SUM('Sep20'!C6:G6) -> 0 | Y11: =SUM('Oct20'!C6:G6) -> 0 | Z11: =SUM('Nov20'!C6:G6) -> 0 | AA11: =SUM('Dec20'!C6:G6) -> 0 | AB11: =SUM(P11:AA11) -> 3217 | AC11: =O11+AB11 -> 8337
B12: Singletons | C12: =SUM(Jan!C7:G7) -> 429 | D12: =SUM(Feb!C7:G7) -> 370 | E12: =SUM(Mar!C7:G7) -> 438 | F12: =SUM(Apr!C7:G7) -> 406 | G12: =SUM(May!C7:G7) -> 461 | H12: =SUM(Jun!C7:G7) -> 425 | I12: =SUM(Jul!C7:G7) -> 422 | J12: =SUM(Aug!C7:G7) -> 386 | K12: =SUM(Sep!C7:G7) -> 463 | L12: =SUM(Oct!C7:G7) -> 394 | M12: =SUM(Nov!C7:G7) -> 378 | N12: =SUM(Dec!C7:G7) -> 413 | O12: =SUM(C12:N12) -> 4985 | P12: =SUM('Jan20'!C7:G7) -> 458 | Q12: =SUM('Feb20'!C7:G7) -> 484 | R12: =SUM('Mar20'!C7:G7) -> 506 | S12: =SUM('Apr20'!C7:G7) -> 540 | T12: =SUM('May20'!C7:G7) -> 593 | U12: =SUM('Jun20'!C7:G7) -> 562 | V12: =SUM('Jul20'!C7:G7) -> 0 | W12: =SUM('Aug20'!C7:G7) -> 0 | X12: =SUM('Sep20'!C7:G7) -> 0 | Y12: =SUM('Oct20'!C7:G7) -> 0 | Z12: =SUM('Nov20'!C7:G7) -> 0 | AA12: =SUM('Dec20'!C7:G7) -> 0 | AB12: =SUM(P12:AA12) -> 3143 | AC12: =O12+AB12 -> 8128
B13: Twins | C13: =SUM(Jan!C8:G8) -> 10 | D13: =SUM(Feb!C8:G8) -> 7 | E13: =SUM(Mar!C8:G8) -> 7 | F13: =SUM(Apr!C8:G8) -> 5 | G13: =SUM(May!C8:G8) -> 3 | H13: =SUM(Jun!C8:G8) -> 3 | I13: =SUM(Jul!C8:G8) -> 12 | J13: =SUM(Aug!C8:G8) -> 5 | K13: =SUM(Sep!C8:G8) -> 8 | L13: =SUM(Oct!C8:G8) -> 10 | M13: =SUM(Nov!C8:G8) -> 10 | N13: =SUM(Dec!C8:G8) -> 19 | O13: =SUM(C13:N13) -> 99 | P13: =SUM('Jan20'!C8:G8) -> 4 | Q13: =SUM('Feb20'!C8:G8) -> 30 | R13: =SUM('Mar20'!C8:G8) -> 6 | S13: =SUM('Apr20'!C8:G8) -> 6 | T13: =SUM('May20'!C8:G8) -> 10 | U13: =SUM('Jun20'!C8:G8) -> 18 | V13: =SUM('Jul20'!C8:G8) -> 0 | W13: =SUM('Aug20'!C8:G8) -> 0 | X13: =SUM('Sep20'!C8:G8) -> 0 | Y13: =SUM('Oct20'!C8:G8) -> 0 | Z13: =SUM('Nov20'!C8:G8) -> 0 | AA13: =SUM('Dec20'!C8:G8) -> 0 | AB13: =SUM(P13:AA13) -> 74 | AC13: =O13+AB13 -> 173
B14: Stillbirths | C14: =SUM(Jan!C9:G9) -> 8 | D14: =SUM(Feb!C9:G9) -> 10 | E14: =SUM(Mar!C9:G9) -> 11 | F14: =SUM(Apr!C9:G9) -> 4 | G14: =SUM(May!C9:G9) -> 9 | H14: =SUM(Jun!C9:G9) -> 5 | I14: =SUM(Jul!C9:G9) -> 6 | J14: =SUM(Aug!C9:G9) -> 11 | K14: =SUM(Sep!C9:G9) -> 6 | L14: =SUM(Oct!C9:G9) -> 6 | M14: =SUM(Nov!C9:G9) -> 10 | N14: =SUM(Dec!C9:G9) -> 11 | O14: =SUM(C14:N14) -> 97 | P14: =SUM('Jan20'!C9:G9) -> 9 | Q14: =SUM('Feb20'!C9:G9) -> 9 | R14: =SUM('Mar20'!C9:G9) -> 12 | S14: =SUM('Apr20'!C9:G9) -> 13 | T14: =SUM('May20'!C9:G9) -> 8 | U14: =SUM('Jun20'!C9:G9) -> 15 | V14: =SUM('Jul20'!C9:G9) -> 0 | W14: =SUM('Aug20'!C9:G9) -> 0 | X14: =SUM('Sep20'!C9:G9) -> 0 | Y14: =SUM('Oct20'!C9:G9) -> 0 | Z14: =SUM('Nov20'!C9:G9) -> 0 | AA14: =SUM('Dec20'!C9:G9) -> 0 | AB14: =SUM(P14:AA14) -> 66 | AC14: =O14+AB14 -> 163
B15: Antepartum | C15: =SUM(Jan!C10:G10) -> 4 | D15: =SUM(Feb!C10:G10) -> 6 | E15: =SUM(Mar!C10:G10) -> 5 | F15: =SUM(Apr!C10:G10) -> 2 | G15: =SUM(May!C10:G10) -> 6 | H15: =SUM(Jun!C10:G10) -> 2 | I15: =SUM(Jul!C10:G10) -> 4 | J15: =SUM(Aug!C10:G10) -> 8 | K15: =SUM(Sep!C10:G10) -> 3 | L15: =SUM(Oct!C10:G10) -> 2 | M15: =SUM(Nov!C10:G10) -> 6 | N15: =SUM(Dec!C10:G10) -> 5 | O15: =SUM(C15:N15) -> 53 | P15: =SUM('Jan20'!C10:G10) -> 4 | Q15: =SUM('Feb20'!C10:G10) -> 5 | R15: =SUM('Mar20'!C10:G10) -> 5 | S15: =SUM('Apr20'!C10:G10) -> 9 | T15: =SUM('May20'!C10:G10) -> 6 | U15: =SUM('Jun20'!C10:G10) -> 13 | V15: =SUM('Jul20'!C10:G10) -> 0 | W15: =SUM('Aug20'!C10:G10) -> 0 | X15: =SUM('Sep20'!C10:G10) -> 0 | Y15: =SUM('Oct20'!C10:G10) -> 0 | Z15: =SUM('Nov20'!C10:G10) -> 0 | AA15: =SUM('Dec20'!C10:G10) -> 0 | AB15: =SUM(P15:AA15) -> 42 | AC15: =O15+AB15 -> 95
B16: Intrapartum | C16: =SUM(Jan!C11:G11) -> 4 | D16: =SUM(Feb!C11:G11) -> 4 | E16: =SUM(Mar!C11:G11) -> 6 | F16: =SUM(Apr!C11:G11) -> 2 | G16: =SUM(May!C11:G11) -> 3 | H16: =SUM(Jun!C11:G11) -> 3 | I16: =SUM(Jul!C11:G11) -> 2 | J16: =SUM(Aug!C11:G11) -> 3 | K16: =SUM(Sep!C11:G11) -> 3 | L16: =SUM(Oct!C11:G11) -> 4 | M16: =SUM(Nov!C11:G11) -> 4 | N16: =SUM(Dec!C11:G11) -> 6 | O16: =SUM(C16:N16) -> 44 | P16: =SUM('Jan20'!C11:G11) -> 5 | Q16: =SUM('Feb20'!C11:G11) -> 4 | R16: =SUM('Mar20'!C11:G11) -> 7 | S16: =SUM('Apr20'!C11:G11) -> 4 | T16: =SUM('May20'!C11:G11) -> 2 | U16: =SUM('Jun20'!C11:G11) -> 2 | V16: =SUM('Jul20'!C11:G11) -> 0 | W16: =SUM('Aug20'!C11:G11) -> 0 | X16: =SUM('Sep20'!C11:G11) -> 0 | Y16: =SUM('Oct20'!C11:G11) -> 0 | Z16: =SUM('Nov20'!C11:G11) -> 0 | AA16: =SUM('Dec20'!C11:G11) -> 0 | AB16: =SUM(P16:AA16) -> 24 | AC16: =O16+AB16 -> 68
B17: Livebirths | C17: =SUM(Jan!C12:G12) -> 439 | D17: =SUM(Feb!C12:G12) -> 374 | E17: =SUM(Mar!C12:G12) -> 441 | F17: =SUM(Apr!C12:G12) -> 416 | G17: =SUM(May!C12:G12) -> 461 | H17: =SUM(Jun!C12:G12) -> 425 | I17: =SUM(Jul!C12:G12) -> 428 | J17: =SUM(Aug!C12:G12) -> 379 | K17: =SUM(Sep!C12:G12) -> 465 | L17: =SUM(Oct!C12:G12) -> 381 | M17: =SUM(Nov!C12:G12) -> 378 | N17: =SUM(Dec!C12:G12) -> 421 | O17: =SUM(C17:N17) -> 5008 | P17: =SUM('Jan20'!C12:G12) -> 453 | Q17: =SUM('Feb20'!C12:G12) -> 505 | R17: =SUM('Mar20'!C12:G12) -> 500 | S17: =SUM('Apr20'!C12:G12) -> 533 | T17: =SUM('May20'!C12:G12) -> 595 | U17: =SUM('Jun20'!C12:G12) -> 565 | V17: =SUM('Jul20'!C12:G12) -> 0 | W17: =SUM('Aug20'!C12:G12) -> 0 | X17: =SUM('Sep20'!C12:G12) -> 0 | Y17: =SUM('Oct20'!C12:G12) -> 0 | Z17: =SUM('Nov20'!C12:G12) -> 0 | AA17: =SUM('Dec20'!C12:G12) -> 0 | AB17: =SUM(P17:AA17) -> 3151 | AC17: =O17+AB17 -> 8159
B18: Term births (≥37 completed weeks) | C18: =SUM(Jan!C13:G13) -> 0 | D18: =SUM(Feb!C13:G13) -> 0 | E18: =SUM(Mar!C13:G13) -> 0 | F18: =SUM(Apr!C13:G13) -> 0 | G18: =SUM(May!C13:G13) -> 0 | H18: =SUM(Jun!C13:G13) -> 0 | I18: =SUM(Jul!C13:G13) -> 407 | J18: =SUM(Aug!C13:G13) -> 0 | K18: =SUM(Sep!C13:G13) -> 456 | L18: =SUM(Oct!C13:G13) -> 364 | M18: =SUM(Nov!C13:G13) -> 362 | N18: =SUM(Dec!C13:G13) -> 407 | O18: =SUM(C18:N18) -> 1996 | P18: =SUM('Jan20'!C13:G13) -> 437 | Q18: =SUM('Feb20'!C13:G13) -> 493 | R18: =SUM('Mar20'!C13:G13) -> 482 | S18: =SUM('Apr20'!C13:G13) -> 517 | T18: =SUM('May20'!C13:G13) -> 575 | U18: =SUM('Jun20'!C13:G13) -> 547 | V18: =SUM('Jul20'!C13:G13) -> 0 | W18: =SUM('Aug20'!C13:G13) -> 0 | X18: =SUM('Sep20'!C13:G13) -> 0 | Y18: =SUM('Oct20'!C13:G13) -> 0 | Z18: =SUM('Nov20'!C13:G13) -> 0 | AA18: =SUM('Dec20'!C13:G13) -> 0 | AB18: =SUM(P18:AA18) -> 3051 | AC18: =O18+AB18 -> 5047
... B23: Very low birth weight babies (<1.5kg) | C23: =SUM(Jan!C18:G18) -> 0 | D23: =SUM(Feb!C18:G18) -> 0 | E23: =SUM(Mar!C18:G18) -> 0 | F23: =SUM(Apr!C18:G18) -> 0 | G23: =SUM(May!C18:G18) -> 0 | H23: =SUM(Jun!C18:G18) -> 0 | I23: =SUM(Jul!C18:G18) -> 0 | J23: =SUM(Aug!C18:G18) -> 3 | K23: =SUM(Sep!C18:G18) -> 0 | L23: =SUM(Oct!C18:G18) -> 0 | M23: =SUM(Nov!C18:G18) -> 0 | N23: =SUM(Dec!C18:G18) -> 0 | O23: =SUM(C23:N23) -> 3 | P23: =SUM('Jan20'!C18:G18) -> 0 | Q23: =SUM('Feb20'!C18:G18) -> 0 | R23: =SUM('Mar20'!C18:G18) -> 0 | S23: =SUM('Apr20'!C18:G18) -> 0 | T23: =SUM('May20'!C18:G18) -> 0 | U23: =SUM('Jun20'!C18:G18) -> 0 | V23: =SUM('Jul20'!C18:G18) -> 0 | W23: =SUM('Aug20'!C18:G18) -> 0 | X23: =SUM('Sep20'!C18:G18) -> 0 | Y23: =SUM('Oct20'!C18:G18) -> 0 | Z23: =SUM('Nov20'!C18:G18) -> 0 | AA23: =SUM('Dec20'!C18:G18) -> 0 | AB23: =SUM(P23:AA23) -> 0 | AC23: =O23+AB23 -> 3
B24: Extremely low birthweight babies (<1.0kg) | C24: =SUM(Jan!C19:G19) -> 0 | D24: =SUM(Feb!C19:G19) -> 0 | E24: =SUM(Mar!C19:G19) -> 0 | F24: =SUM(Apr!C19:G19) -> 0 | G24: =SUM(May!C19:G19) -> 0 | H24: =SUM(Jun!C19:G19) -> 0 | I24: =SUM(Jul!C19:G19) -> 0 | J24: =SUM(Aug!C19:G19) -> 0 | K24: =SUM(Sep!C19:G19) -> 0 | L24: =SUM(Oct!C19:G19) -> 0 | M24: ] | N24: =SUM(Dec!C19:G19) -> 0 | O24: =SUM(C24:N24) -> 0 | P24: =SUM('Jan20'!C19:G19) -> 0 | Q24: =SUM('Feb20'!C19:G19) -> 0 | R24: =SUM('Mar20'!C19:G19) -> 0 | S24: =SUM('Apr20'!C19:G19) -> 0 | T24: =SUM('May20'!C19:G19) -> 0 | U24: =SUM('Jun20'!C19:G19) -> 0 | V24: =SUM('Jul20'!C19:G19) -> 0 | W24: =SUM('Aug20'!C19:G19) -> 0 | X24: =SUM('Sep20'!C19:G19) -> 0 | Y24: =SUM('Oct20'!C19:G19) -> 0 | Z24: =SUM('Nov20'!C19:G19) -> 0 | AA24: =SUM('Dec20'!C19:G19) -> 0 | AB24: =SUM(P24:AA24) -> 0 | AC24: =O24+AB24 -> 0
B25: Neonatal deaths | C25: =SUM(Jan!C20:G20) -> 5 | D25: =SUM(Feb!C20:G20) -> 7 | E25: =SUM(Mar!C20:G20) -> 8 | F25: =SUM(Apr!C20:G20) -> 10 | G25: =SUM(May!C20:G20) -> 5 | H25: =SUM(Jun!C20:G20) -> 5 | I25: =SUM(Jul!C20:G20) -> 2 | J25: =SUM(Aug!C20:G20) -> 2 | K25: =SUM(Sep!C20:G20) -> 1 | L25: =SUM(Oct!C20:G20) -> 12 | M25: =SUM(Nov!C20:G20) -> 4 | N25: =SUM(Dec!C20:G20) -> 9 | O25: =SUM(C25:N25) -> 70 | P25: =SUM('Jan20'!C20:G20) -> 6 | Q25: =SUM('Feb20'!C20:G20) -> 7 | R25: =SUM('Mar20'!C20:G20) -> 5 | S25: =SUM('Apr20'!C20:G20) -> 5 | T25: =SUM('May20'!C20:G20) -> 11 | U25: =SUM('Jun20'!C20:G20) -> 15 | V25: =SUM('Jul20'!C20:G20) -> 0 | W25: =SUM('Aug20'!C20:G20) -> 0 | X25: =SUM('Sep20'!C20:G20) -> 0 | Y25: =SUM('Oct20'!C20:G20) -> 0 | Z25: =SUM('Nov20'!C20:G20) -> 0 | AA25: =SUM('Dec20'!C20:G20) -> 0 | AB25: =SUM(P25:AA25) -> 49 | AC25: =O25+AB25 -> 119
B26: Early Neonatal Deaths (0-6 days) | C26: =SUM(Jan!C21:G21) -> 3 | D26: =SUM(Feb!C21:G21) -> 6 | E26: =SUM(Mar!C21:G21) -> 5 | F26: =SUM(Apr!C21:G21) -> 7 | G26: =SUM(May!C21:G21) -> 5 | H26: =SUM(Jun!C21:G21) -> 3 | I26: =SUM(Jul!C21:G21) -> 2 | J26: =SUM(Aug!C21:G21) -> 2 | K26: =SUM(Sep!C21:G21) -> 1 | L26: =SUM(Oct!C21:G21) -> 10 | M26: =SUM(Nov!C21:G21) -> 3 | N26: =SUM(Dec!C21:G21) -> 7 | O26: =SUM(C26:N26) -> 54 | P26: =SUM('Jan20'!C21:G21) -> 4 | Q26: =SUM('Feb20'!C21:G21) -> 5 | R26: =SUM('Mar20'!C21:G21) -> 4 | S26: =SUM('Apr20'!C21:G21) -> 5 | T26: =SUM('May20'!C21:G21) -> 10 | U26: =SUM('Jun20'!C21:G21) -> 13 | V26: =SUM('Jul20'!C21:G21) -> 0 | W26: =SUM('Aug20'!C21:G21) -> 0 | X26: =SUM('Sep20'!C21:G21) -> 0 | Y26: =SUM('Oct20'!C21:G21) -> 0 | Z26: =SUM('Nov20'!C21:G21) -> 0 | AA26: =SUM('Dec20'!C21:G21) -> 0 | AB26: =SUM(P26:AA26) -> 41 | AC26: =O26+AB26 -> 95
B27: Late Neonatal Deaths (7-27 days) | C27: =SUM(Jan!C22:G22) -> 2 | D27: =SUM(Feb!C22:G22) -> 1 | E27: =SUM(Mar!C22:G22) -> 3 | F27: =SUM(Apr!C22:G22) -> 3 | G27: =SUM(May!C22:G22) -> 0 | H27: =SUM(Jun!C22:G22) -> 2 | I27: =SUM(Jul!C22:G22) -> 0 | J27: =SUM(Aug!C22:G22) -> 0 | K27: =SUM(Sep!C22:G22) -> 0 | L27: =SUM(Oct!C22:G22) -> 2 | M27: =SUM(Nov!C22:G22) -> 1 | N27: =SUM(Dec!C22:G22) -> 2 | O27: =SUM(C27:N27) -> 16 | P27: =SUM('Jan20'!C22:G22) -> 2 | Q27: =SUM('Feb20'!C22:G22) -> 2 | R27: =SUM('Mar20'!C22:G22) -> 1 | S27: =SUM('Apr20'!C22:G22) -> 0 | T27: =SUM('May20'!C22:G22) -> 1 | U27: =SUM('Jun20'!C22:G22) -> 2 | V27: =SUM('Jul20'!C22:G22) -> 0 | W27: =SUM('Aug20'!C22:G22) -> 0 | X27: =SUM('Sep20'!C22:G22) -> 0 | Y27: =SUM('Oct20'!C22:G22) -> 0 | Z27: =SUM('Nov20'!C22:G22) -> 0 | AA27: =SUM('Dec20'!C22:G22) -> 0 | AB27: =SUM(P27:AA27) -> 8 | AC27: =O27+AB27 -> 24
B28: Maternal deaths | C28: =SUM(Jan!C23:G23) -> 0 | D28: =SUM(Feb!C23:G23) -> 2 | E28: =SUM(Mar!C23:G23) -> 2 | F28: =SUM(Apr!C23:G23) -> 1 | G28: =SUM(May!C23:G23) -> 3 | H28: =SUM(Jun!C23:G23) -> 1 | I28: =SUM(Jul!C23:G23) -> 1 | J28: =SUM(Aug!C23:G23) -> 2 | K28: =SUM(Sep!C23:G23) -> 2 | L28: =SUM(Oct!C23:G23) -> 1 | M28: =SUM(Nov!C23:G23) -> 0 | N28: =SUM(Dec!C23:G23) -> 1 | O28: =SUM(C28:N28) -> 16 | P28: =SUM('Jan20'!C23:G23) -> 1 | Q28: =SUM('Feb20'!C23:G23) -> 1 | R28: =SUM('Mar20'!C23:G23) -> 0 | S28: =SUM('Apr20'!C23:G23) -> 0 | T28: =SUM('May20'!C23:G23) -> 0 | U28: =SUM('Jun20'!C23:G23) -> 2 | V28: =SUM('Jul20'!C23:G23) -> 0 | W28: =SUM('Aug20'!C23:G23) -> 0 | X28: =SUM('Sep20'!C23:G23) -> 0 | Y28: =SUM('Oct20'!C23:G23) -> 0 | Z28: =SUM('Nov20'!C23:G23) -> 0 | AA28: =SUM('Dec20'!C23:G23) -> 0 | AB28: =SUM(P28:AA28) -> 4 | AC28: =O28+AB28 -> 20

Sheet Indicators
B1: Key Institutional Indicators: | C1: Overall average | D1: 43466 | E1: 43497 | F1: 43525 | G1: 43556 | H1: 43586 | I1: 43617 | J1: 43647 | K1: 43678 | L1: 43709 | M1: 43739 | N1: 43770 | O1: 43800 | P1: 2020 average | Q1: 43831 | R1: 43862 | S1: 43891 | T1: 43922 | U1: 43952 | V1: 43983 | W1: 44013 | X1: 44044 | Y1: 44075 | Z1: 44105 | AA1: 44136 | AB1: 44166
A2: Home | B2: Stillbirth rate (iSBR) | C2: =1000*('Annual log'!AC14/'Annual log'!AC11) -> 19.551397 | D2: =1000*('Annual log'!C14/'Annual log'!C11) -> 17.897092 | E2: =1000*('Annual log'!D14/'Annual log'!D11) -> 26.041667 | F2: =1000*('Annual log'!E14/'Annual log'!E11) -> 24.444444 | G2: =1000*('Annual log'!F14/'Annual log'!F11) -> 9.5238095 | H2: =1000*('Annual log'!G14/'Annual log'!G11) -> 19.148936 | I2: =1000*('Annual log'!H14/'Annual log'!H11) -> 11.627907 | J2: =1000*('Annual log'!I14/'Annual log'!I11) -> 13.824885 | K2: =1000*('Annual log'!J14/'Annual log'!J11) -> 28.205128 | ... O2: =1000*('Annual log'!N14/'Annual log'!N11) -> 25.462963 | P2: =1000*('Annual log'!AB14/'Annual log'!AB11) -> 20.516009 | Q2: =1000*('Annual log'!P14/'Annual log'!P11) -> 19.480519 | R2: =1000*('Annual log'!Q14/'Annual log'!Q11) -> 17.509728 | S2: =1000*('Annual log'!R14/'Annual log'!R11) -> 23.4375 | T2: =1000*('Annual log'!S14/'Annual log'!S11) -> 23.809524 | U2: =1000*('Annual log'!T14/'Annual log'!T11) -> 13.266998 | V2: =1000*('Annual log'!U14/'Annual log'!U11) -> 25.862069 | W2: =1000*('Annual log'!V14/'Annual log'!V11) -> #DIV/0! | X2: =1000*('Annual log'!W14/'Annual log'!W11) -> #DIV/0! | ... AB2: =1000*('Annual log'!AA14/'Annual log'!AA11) -> #DIV/0!
B3: % Intrapartum Stillbirths | C3: ='Annual log'!AC16/'Annual log'!AC14 -> 0.41717791 | D3: ='Annual log'!C16/'Annual log'!C14 -> 0.5 | E3: ='Annual log'!D16/'Annual log'!D14 -> 0.4 | F3: ='Annual log'!E16/'Annual log'!E14 -> 0.54545455 | G3: ='Annual log'!F16/'Annual log'!F14 -> 0.5 | H3: ='Annual log'!G16/'Annual log'!G14 -> 0.33333333 | I3: ='Annual log'!H16/'Annual log'!H14 -> 0.6 | J3: ='Annual log'!I16/'Annual log'!I14 -> 0.33333333 | K3: ='Annual log'!J16/'Annual log'!J14 -> 0.27272727 | ... O3: ='Annual log'!N16/'Annual log'!N14 -> 0.54545455 | P3: ='Annual log'!AB16/'Annual log'!AB14 -> 0.36363636 | Q3: ='Annual log'!P16/'Annual log'!P14 -> 0.55555556 | R3: ='Annual log'!Q16/'Annual log'!Q14 -> 0.44444444 | S3: ='Annual log'!R16/'Annual log'!R14 -> 0.58333333 | T3: ='Annual log'!S16/'Annual log'!S14 -> 0.30769231 | U3: ='Annual log'!T16/'Annual log'!T14 -> 0.25 | V3: ='Annual log'!U16/'Annual log'!U14 -> 0.13333333 | W3: ='Annual log'!V16/'Annual log'!V14 -> #DIV/0! | X3: ='Annual log'!W16/'Annual log'!W14 -> #DIV/0! | ... AB3: ='Annual log'!AA16/'Annual log'!AA14 -> #DIV/0!
B4: Early Neonatal Mortality Rate (iENMR) | C4: =1000*('Annual log'!AC26/'Annual log'!AC17) -> 11.643584 | D4: =1000*('Annual log'!C26/'Annual log'!C17) -> 6.833713 | E4: =1000*('Annual log'!D26/'Annual log'!D17) -> 16.042781 | F4: =1000*('Annual log'!E26/'Annual log'!E17) -> 11.337868 | G4: =1000*('Annual log'!F26/'Annual log'!F17) -> 16.826923 | H4: =1000*('Annual log'!G26/'Annual log'!G17) -> 10.845987 | I4: =1000*('Annual log'!H26/'Annual log'!H17) -> 7.0588235 | J4: =1000*('Annual log'!I26/'Annual log'!I17) -> 4.6728972 | K4: =1000*('Annual log'!J26/'Annual log'!J17) -> 5.2770449 | ... O4: =1000*('Annual log'!N26/'Annual log'!N17) -> 16.627078 | P4: =1000*('Annual log'!AB26/'Annual log'!AB17) -> 13.011742 | Q4: =1000*('Annual log'!P26/'Annual log'!P17) -> 8.8300221 | R4: =1000*('Annual log'!Q26/'Annual log'!Q17) -> 9.9009901 | S4: =1000*('Annual log'!R26/'Annual log'!R17) -> 8 | T4: =1000*('Annual log'!S26/'Annual log'!S17) -> 9.380863 | U4: =1000*('Annual log'!T26/'Annual log'!T17) -> 16.806723 | V4: =1000*('Annual log'!U26/'Annual log'!U17) -> 23.00885 | W4: =1000*('Annual log'!V26/'Annual log'!V17) -> #DIV/0! | X4: =1000*('Annual log'!W26/'Annual log'!W17) -> #DIV/0! | ... AB4: =1000*('Annual log'!AA26/'Annual log'!AA17) -> #DIV/0!
B5: Perinatal Mortality Rate (iPMR) | C5: =1000*(('Annual log'!AC26+'Annual log'!AC14)/'Annual log'!AC11) -> 30.946384 | D5: =1000*(('Annual log'!C26+'Annual log'!C14)/'Annual log'!C11) -> 24.608501 | E5: =1000*(('Annual log'!D26+'Annual log'!D14)/'Annual log'!D11) -> 41.666667 | F5: =1000*(('Annual log'!E26+'Annual log'!E14)/'Annual log'!E11) -> 35.555556 | G5: =1000*(('Annual log'!F26+'Annual log'!F14)/'Annual log'!F11) -> 26.190476 | H5: =1000*(('Annual log'!G26+'Annual log'!G14)/'Annual log'!G11) -> 29.787234 | I5: =1000*(('Annual log'!H26+'Annual log'!H14)/'Annual log'!H11) -> 18.604651 | J5: =1000*(('Annual log'!I26+'Annual log'!I14)/'Annual log'!I11) -> 18.43318 | K5: =1000*(('Annual log'!J26+'Annual log'!J14)/'Annual log'!J11) -> 33.333333 | ... O5: =1000*(('Annual log'!N26+'Annual log'!N14)/'Annual log'!N11) -> 41.666667 | P5: =1000*(('Annual log'!AB26+'Annual log'!AB14)/'Annual log'!AB11) -> 33.260802 | Q5: =1000*(('Annual log'!P26+'Annual log'!P14)/'Annual log'!P11) -> 28.138528 | R5: =1000*(('Annual log'!Q26+'Annual log'!Q14)/'Annual log'!Q11) -> 27.237354 | S5: =1000*(('Annual log'!R26+'Annual log'!R14)/'Annual log'!R11) -> 31.25 | T5: =1000*(('Annual log'!S26+'Annual log'!S14)/'Annual log'!S11) -> 32.967033 | U5: =1000*(('Annual log'!T26+'Annual log'!T14)/'Annual log'!T11) -> 29.850746 | V5: =1000*(('Annual log'!U26+'Annual log'!U14)/'Annual log'!U11) -> 48.275862 | W5: =1000*(('Annual log'!V26+'Annual log'!V14)/'Annual log'!V11) -> #DIV/0! | X5: =1000*(('Annual log'!W26+'Annual log'!W14)/'Annual log'!W11) -> #DIV/0! | ... AB5: =1000*(('Annual log'!AA26+'Annual log'!AA14)/'Annual log'!AA11) -> #DIV/0!
B6: Neonatal Mortality Rate (iNMR) | C6: =1000*('Annual log'!AC25/'Annual log'!AC17) -> 14.585121 | D6: =1000*('Annual log'!C25/'Annual log'!C17) -> 11.389522 | E6: =1000*('Annual log'!D25/'Annual log'!D17) -> 18.716578 | F6: =1000*('Annual log'!E25/'Annual log'!E17) -> 18.14059 | G6: =1000*('Annual log'!F25/'Annual log'!F17) -> 24.038462 | H6: =1000*('Annual log'!G25/'Annual log'!G17) -> 10.845987 | I6: =1000*('Annual log'!H25/'Annual log'!H17) -> 11.764706 | J6: =1000*('Annual log'!I25/'Annual log'!I17) -> 4.6728972 | K6: =1000*('Annual log'!J25/'Annual log'!J17) -> 5.2770449 | ... O6: =1000*('Annual log'!N25/'Annual log'!N17) -> 21.377672 | P6: =1000*('Annual log'!AB25/'Annual log'!AB17) -> 15.550619 | Q6: =1000*('Annual log'!P25/'Annual log'!P17) -> 13.245033 | R6: =1000*('Annual log'!Q25/'Annual log'!Q17) -> 13.861386 | S6: =1000*('Annual log'!R25/'Annual log'!R17) -> 10 | T6: =1000*('Annual log'!S25/'Annual log'!S17) -> 9.380863 | U6: =1000*('Annual log'!T25/'Annual log'!T17) -> 18.487395 | V6: =1000*('Annual log'!U25/'Annual log'!U17) -> 26.548673 | W6: =1000*('Annual log'!V25/'Annual log'!V17) -> #DIV/0! | X6: =1000*('Annual log'!W25/'Annual log'!W17) -> #DIV/0! | ... AB6: =1000*('Annual log'!AA25/'Annual log'!AA17) -> #DIV/0!
B7: Maternal Mortality Ratio (iMMR) | C7: =100000*('Annual log'!AC28/'Annual log'!AC17) -> 245.12808 | D7: =100000*('Annual log'!C28/'Annual log'!C17) -> 0 | E7: =100000*('Annual log'!D28/'Annual log'!D17) -> 534.75936 | F7: =100000*('Annual log'!E28/'Annual log'!E17) -> 453.51474 | G7: =100000*('Annual log'!F28/'Annual log'!F17) -> 240.38462 | H7: =100000*('Annual log'!G28/'Annual log'!G17) -> 650.75922 | I7: =100000*('Annual log'!H28/'Annual log'!H17) -> 235.29412 | J7: =100000*('Annual log'!I28/'Annual log'!I17) -> 233.64486 | K7: =100000*('Annual log'!J28/'Annual log'!J17) -> 527.70449 | ... O7: =100000*('Annual log'!N28/'Annual log'!N17) -> 237.52969 | P7: =100000*('Annual log'!AB28/'Annual log'!AB17) -> 126.94383 | Q7: =100000*('Annual log'!P28/'Annual log'!P17) -> 220.75055 | R7: =100000*('Annual log'!Q28/'Annual log'!Q17) -> 198.0198 | S7: =100000*('Annual log'!R28/'Annual log'!R17) -> 0 | T7: =100000*('Annual log'!S28/'Annual log'!S17) -> 0 | U7: =100000*('Annual log'!T28/'Annual log'!T17) -> 0 | V7: =100000*('Annual log'!U28/'Annual log'!U17) -> 353.9823 | W7: =100000*('Annual log'!V28/'Annual log'!V17) -> #DIV/0! | X7: =100000*('Annual log'!W28/'Annual log'!W17) -> #DIV/0! | ... AB7: =100000*('Annual log'!AA28/'Annual log'!AA17) -> #DIV/0!
B8: Caesarean Section Rate (CSR) | C8: ='Annual log'!AC10/'Annual log'!AC7 -> 0.16670714 | D8: =('Annual log'!C10/'Annual log'!C7) -> 0.18362832 | E8: =('Annual log'!D10/'Annual log'!D7) -> 0.15384615 | F8: =('Annual log'!E10/'Annual log'!E7) -> 0.19550562 | G8: =('Annual log'!F10/'Annual log'!F7) -> 0.19951338 | H8: =('Annual log'!G10/'Annual log'!G7) -> 0.18103448 | I8: =('Annual log'!H10/'Annual log'!H7) -> 0.1728972 | J8: =('Annual log'!I10/'Annual log'!I7) -> 0.18457944 | K8: =('Annual log'!J10/'Annual log'!J7) -> 0.17647059 | ... O8: =('Annual log'!N10/'Annual log'!N7) -> 0.17917676 | P8: ='Annual log'!AB10/'Annual log'!AB7 -> 0.15287826 | Q8: =('Annual log'!P10/'Annual log'!P7) -> 0.14718615 | R8: =('Annual log'!Q10/'Annual log'!Q7) -> 0.14629259 | S8: =('Annual log'!R10/'Annual log'!R7) -> 0.1453831 | T8: =('Annual log'!S10/'Annual log'!S7) -> 0.14814815 | U8: =('Annual log'!T10/'Annual log'!T7) -> 0.15886288 | V8: =('Annual log'!U10/'Annual log'!U7) -> 0.16812609 | W8: =('Annual log'!V10/'Annual log'!V7) -> #DIV/0! | X8: =('Annual log'!W10/'Annual log'!W7) -> #DIV/0! | ... AB8: =('Annual log'!AA10/'Annual log'!AA7) -> #DIV/0!
B9: % of Assisted Deliveries | C9: ='Annual log'!AC9/'Annual log'!AC7 -> 0.010927635 | D9: ='Annual log'!C9/'Annual log'!C7 -> 0.0022123894 | E9: ='Annual log'!D9/'Annual log'!D7 -> 0.015915119 | F9: ='Annual log'!E9/'Annual log'!E7 -> 0.002247191 | G9: ='Annual log'!F9/'Annual log'!F7 -> 0.01946472 | H9: ='Annual log'!G9/'Annual log'!G7 -> 0.0086206897 | I9: ='Annual log'!H9/'Annual log'!H7 -> 0.0046728972 | J9: ='Annual log'!I9/'Annual log'!I7 -> 0.01635514 | K9: ='Annual log'!J9/'Annual log'!J7 -> 0.010230179 | ... O9: ='Annual log'!N9/'Annual log'!N7 -> 0 | P9: ='Annual log'!AB9/'Annual log'!AB7 -> 0.014155395 | Q9: ='Annual log'!P9/'Annual log'!P7 -> 0.0021645022 | R9: ='Annual log'!Q9/'Annual log'!Q7 -> 0.016032064 | S9: ='Annual log'!R9/'Annual log'!R7 -> 0.0039292731 | T9: ='Annual log'!S9/'Annual log'!S7 -> 0.024074074 | U9: ='Annual log'!T9/'Annual log'!T7 -> 0.025083612 | V9: ='Annual log'!U9/'Annual log'!U7 -> 0.010507881 | W9: ='Annual log'!V9/'Annual log'!V7 -> #DIV/0! | X9: ='Annual log'!W9/'Annual log'!W7 -> #DIV/0! | ... AB9: ='Annual log'!AA9/'Annual log'!AA7 -> #DIV/0!
B10: Low Birthweight Rate (iLBWR) | C10: ='Annual log'!AC22/'Annual log'!AC17 -> 0.10748866 | D10: ='Annual log'!C22/'Annual log'!C17 -> 0.066059226 | E10: ='Annual log'!D22/'Annual log'!D17 -> 0.10962567 | F10: ='Annual log'!E22/'Annual log'!E17 -> 0.14285714 | G10: ='Annual log'!F22/'Annual log'!F17 -> 0.15144231 | H10: ='Annual log'!G22/'Annual log'!G17 -> 0.11062907 | I10: ='Annual log'!H22/'Annual log'!H17 -> 0.072941176 | J10: ='Annual log'!I22/'Annual log'!I17 -> 0.12383178 | K10: ='Annual log'!J22/'Annual log'!J17 -> 0.14248021 | ... O10: ='Annual log'!N22/'Annual log'!N17 -> 0.09976247 | P10: ='Annual log'!AB22/'Annual log'!AB17 -> 0.1059981 | Q10: ='Annual log'!P22/'Annual log'!P17 -> 0.090507726 | R10: ='Annual log'!Q22/'Annual log'!Q17 -> 0.15643564 | S10: ='Annual log'!R22/'Annual log'!R17 -> 0.12 | T10: ='Annual log'!S22/'Annual log'!S17 -> 0.082551595 | U10: ='Annual log'!T22/'Annual log'!T17 -> 0.094117647 | V10: ='Annual log'!U22/'Annual log'!U17 -> 0.095575221 | W10: ='Annual log'!V22/'Annual log'!V17 -> #DIV/0! | X10: ='Annual log'!W22/'Annual log'!W17 -> #DIV/0! | ... AB10: ='Annual log'!AA22/'Annual log'!AA17 -> #DIV/0!
B11: Preterm Birth Rate (iPTBR) | C11: ='Annual log'!AC19/'Annual log'!AC17 -> 0.021693835 | D11: ='Annual log'!C19/'Annual log'!C17 -> 0 | E11: ='Annual log'!D19/'Annual log'!D17 -> 0 | F11: ='Annual log'!E19/'Annual log'!E17 -> 0 | G11: ='Annual log'!F19/'Annual log'!F17 -> 0 | H11: ='Annual log'!G19/'Annual log'!G17 -> 0 | I11: ='Annual log'!H19/'Annual log'!H17 -> 0 | J11: ='Annual log'!I19/'Annual log'!I17 -> 0.049065421 | K11: ='Annual log'!J19/'Annual log'!J17 -> 0 | ... O11: ='Annual log'!N19/'Annual log'!N17 -> 0.033254157 | P11: ='Annual log'!AB19/'Annual log'!AB17 -> 0.031735957 | Q11: ='Annual log'!P19/'Annual log'!P17 -> 0.035320088 | R11: ='Annual log'!Q19/'Annual log'!Q17 -> 0.023762376 | S11: ='Annual log'!R19/'Annual log'!R17 -> 0.036 | T11: ='Annual log'!S19/'Annual log'!S17 -> 0.030018762 | U11: ='Annual log'!T19/'Annual log'!T17 -> 0.033613445 | V11: ='Annual log'!U19/'Annual log'!U17 -> 0.031858407 | W11: ='Annual log'!V19/'Annual log'!V17 -> #DIV/0! | X11: ='Annual log'!W19/'Annual log'!W17 -> #DIV/0! | ... AB11: ='Annual log'!AA19/'Annual log'!AA17 -> #DIV/0!
B12: % Neonatal Deaths in 1st week | C12: ='Annual log'!AC26/'Annual log'!AC25 -> 0.79831933 | D12: ='Annual log'!C26/'Annual log'!C25 -> 0.6 | E12: ='Annual log'!D26/'Annual log'!D25 -> 0.85714286 | F12: ='Annual log'!E26/'Annual log'!E25 -> 0.625 | G12: ='Annual log'!F26/'Annual log'!F25 -> 0.7 | H12: ='Annual log'!G26/'Annual log'!G25 -> 1 | I12: ='Annual log'!H26/'Annual log'!H25 -> 0.6 | J12: ='Annual log'!I26/'Annual log'!I25 -> 1 | K12: ='Annual log'!J26/'Annual log'!J25 -> 1 | ... O12: ='Annual log'!N26/'Annual log'!N25 -> 0.77777778 | P12: ='Annual log'!AB26/'Annual log'!AB25 -> 0.83673469 | Q12: ='Annual log'!P26/'Annual log'!P25 -> 0.66666667 | R12: ='Annual log'!Q26/'Annual log'!Q25 -> 0.71428571 | S12: ='Annual log'!R26/'Annual log'!R25 -> 0.8 | T12: ='Annual log'!S26/'Annual log'!S25 -> 1 | U12: ='Annual log'!T26/'Annual log'!T25 -> 0.90909091 | V12: ='Annual log'!U26/'Annual log'!U25 -> 0.86666667 | W12: ='Annual log'!V26/'Annual log'!V25 -> #DIV/0! | X12: ='Annual log'!W26/'Annual log'!W25 -> #DIV/0! | ... AB12: ='Annual log'!AA26/'Annual log'!AA25 -> #DIV/0!
A14: Key Institutional Indicators | C14: Annual Total | D14: 43466 | E14: 43497 | F14: 43525 | G14: 43556 | H14: 43586 | I14: 43617 | J14: 43647 | K14: 43678 | L14: 43709 | M14: 43739 | N14: 43770 | O14: 43800 | Q14: 43831 | R14: 43862 | S14: 43891 | T14: 43922 | U14: 43952 | V14: 43983 | W14: 44013 | X14: 44044 | Y14: 44075 | Z14: 44105 | AA14: 44136 | AB14: 44166
B15: Maternal Deaths | C15: ='Annual log'!AC28 -> 20 | D15: ='Annual log'!C28 -> 0 | E15: ='Annual log'!D28 -> 2 | F15: ='Annual log'!E28 -> 2 | G15: ='Annual log'!F28 -> 1 | H15: ='Annual log'!G28 -> 3 | I15: ='Annual log'!H28 -> 1 | J15: ='Annual log'!I28 -> 1 | K15: ='Annual log'!J28 -> 2 | ... O15: ='Annual log'!N28 -> 1 | P15: ='Annual log'!AB28 -> 4 | Q15: ='Annual log'!P28 -> 1 | R15: ='Annual log'!Q28 -> 1 | S15: ='Annual log'!R28 -> 0 | T15: ='Annual log'!S28 -> 0 | U15: ='Annual log'!T28 -> 0 | V15: ='Annual log'!U28 -> 2 | W15: ='Annual log'!V28 -> 0 | X15: ='Annual log'!W28 -> 0 | ... AB15: ='Annual log'!AA28 -> 0
B19: SVDs | C19: =1-C22 -> 0.82236523 | O19: SVDs | P19: =1-P22 -> 0.83296634
B20: Assisted | C20: =C9 -> 0.010927635 | O20: Assisted | P20: =P9 -> 0.014155395
B21: C-Sections | C21: =C8 -> 0.16670714 | O21: C-Sections | P21: =P8 -> 0.15287826
C22: =C20+C21 -> 0.17763477 | P22: =P20+P21 -> 0.16703366

Sheet Perinatal Deaths
A1: Home

Sheet Neonatal deaths
A1: Home

Sheet Stillbirths
A1: Home

Sheet Preterm&LBW
A1: Home

Sheet Delivery Stats
A1: Home

Sheet Maternal Deaths
A1: Home

Sheet Jan20
A1: mp | B1: Month/Statistic | C1: Week 1 | D1: Week 2 | E1: Week 3 | F1: Week 4 | G1: Week 5 | H1: Recommendations
B2: Total Deliveries | G2: 462
B3: SVDs/NVDs | G3: 393
B4: Assisted | G4: 1
B5: Caesarean Sections | G5: 68
B6: Total Births | G6: 462
B7: Singletons | G7: 458
B8: Multiple | G8: 4
B9: Stillbirths | G9: 9
B10: Antepartum | G10: 4
B11: Intrapartum | G11: 5
B12: Livebirths | G12: 453
B13: Term births (≥37 completed weeks) | G13: 437
B14: Preterms (<37 completed weeks) | G14: 16
B15: Very Preterms (<34 completed weeks)
B16: Normal birthweight babies (≥ 2.5kg) | G16: 412
B17: Low birth weight babies (<2.5kg) | G17: 41
B18: Ver low birthweight babies (<1.5kg)
B19: Extremely low birthweight babies (<1.0kg)
B20: Neonatal deaths | G20: 6
B21: Early Neonatal Deaths (1-7 days) | G21: 4
B22: Late Neonatal Deaths (8-28 days) | G22: 2
B23: Maternal deaths | G23: 1

Sheet Feb20
A1: Home | B1: Month/Statistic | C1: Week 1 | D1: Week 2 | E1: Week 3 | F1: Week 4 | G1: Week 5 | H1: Recommendations
B2: Total Deliveries | G2: 499
B3: SVDs/NVDs | G3: 418
B4: Assisted | G4: 8
B5: Caesarean Sections | G5: 73
B6: Total Births | G6: 514
B7: Singletons | G7: 484
B8: Multiple | G8: 30
B9: Stillbirths | G9: 9
B10: Antepartum | G10: 5
B11: Intrapartum | G11: 4
B12: Livebirths | G12: 505
B13: Term births (≥37 completed weeks) | G13: 493
B14: Preterms (<37 completed weeks) | G14: 12
B15: Very Preterms (<34 completed weeks)
B16: Normal birthweight babies (≥ 2.5kg) | G16: 426
B17: Low birth weight babies (<2.5kg) | G17: 79
B18: Ver low birthweight babies (<1.5kg)
B19: Extremely low birthweight babies (<1.0kg)
B20: Neonatal deaths | G20: 7
B21: Early Neonatal Deaths (1-7 days) | G21: 5
B22: Late Neonatal Deaths (8-28 days) | G22: 2
B23: Maternal deaths | G23: 1

Sheet Mar20
A1: Home | B1: Month/Statistic | C1: Week 1 | D1: Week 2 | E1: Week 3 | F1: Week 4 | G1: Week 5 | H1: Recommendations
B2: Total Deliveries | G2: 509
B3: SVDs/NVDs | G3: 433
B4: Assisted | G4: 2
B5: Caesarean Sections | G5: 74
B6: Total Births | G6: 512
B7: Singletons | G7: 506
B8: Multiple | G8: 6
B9: Stillbirths | G9: 12
B10: Antepartum | G10: 5
B11: Intrapartum | G11: 7
B12: Livebirths | G12: 500
B13: Term births (≥37 completed weeks) | G13: 482
B14: Preterms (<37 completed weeks) | G14: 18
B15: Very Preterms (<34 completed weeks)
B16: Normal birthweight babies (≥ 2.5kg) | G16: 440
B17: Low birth weight babies (<2.5kg) | G17: 60
B18: Ver low birthweight babies (<1.5kg)
B19: Extremely low birthweight babies (<1.0kg)
B20: Neonatal deaths | G20: 5
B21: Early Neonatal Deaths (1-7 days) | G21: 4
B22: Late Neonatal Deaths (8-28 days) | G22: 1
B23: Maternal deaths | G23: 0

Sheet Apr20
A1: Home | B1: Month/Statistic | C1: Week 1 | D1: Week 2 | E1: Week 3 | F1: Week 4 | G1: Week 5 | H1: Recommendations
B2: Total Deliveries | G2: 540
B3: SVDs/NVDs | G3: 447
B4: Assisted | G4: 13
B5: Caesarean Sections | G5: 80
B6: Total Births | G6: 546
B7: Singletons | G7: 540
B8: Multiple | G8: 6
B9: Stillbirths | G9: 13
B10: Antepartum | G10: 9
B11: Intrapartum | G11: 4
B12: Livebirths | G12: 533
B13: Term births (≥37 completed weeks) | G13: 517
B14: Preterms (<37 completed weeks) | G14: 16
B15: Very Preterms (<34 completed weeks)
B16: Normal birthweight babies (≥ 2.5kg) | G16: 489
B17: Low birth weight babies (<2.5kg) | G17: 44
B18: Ver low birthweight babies (<1.5kg)
B19: Extremely low birthweight babies (<1.0kg)
B20: Neonatal deaths | G20: 5
B21: Early Neonatal Deaths (1-7 days) | G21: 5
B22: Late Neonatal Deaths (8-28 days) | G22: 0
B23: Maternal deaths | G23: 0

Sheet May20
A1: Home | B1: Month/Statistic | C1: Week 1 | D1: Week 2 | E1: Week 3 | F1: Week 4 | G1: Week 5 | H1: Recommendations
B2: Total Deliveries | G2: 598
B3: SVDs/NVDs | G3: 488
B4: Assisted | G4: 15
B5: Caesarean Sections | G5: 95
B6: Total Births | G6: 603
B7: Singletons | G7: 593
B8: Multiple | G8: 10
B9: Stillbirths | G9: 8
B10: Antepartum | G10: 6
B11: Intrapartum | G11: 2
B12: Livebirths | G12: 595
B13: Term births (≥37 completed weeks) | G13: 575
B14: Preterms (<37 completed weeks) | G14: 20
B15: Very Preterms (<34 completed weeks)
B16: Normal birthweight babies (≥ 2.5kg) | G16: 539
B17: Low birth weight babies (<2.5kg) | G17: 56
B18: Ver low birthweight babies (<1.5kg)
B19: Extremely low birthweight babies (<1.0kg)
B20: Neonatal deaths | G20: 11
B21: Early Neonatal Deaths (1-7 days) | G21: 10
B22: Late Neonatal Deaths (8-28 days) | G22: 1
B23: Maternal deaths | G23: 0
G24: 0

Sheet Jun20
A1: Home | B1: Month/Statistic | C1: Week 1 | D1: Week 2 | E1: Week 3 | F1: Week 4 | G1: Week 5 | H1: Recommendations
B2: Total Deliveries | G2: 571
B3: SVDs/NVDs | G3: 469
B4: Assisted | G4: 6
B5: Caesarean Sections | G5: 96
B6: Total Births | G6: 580
B7: Singletons | G7: 562
B8: Multiple | G8: 18
B9: Stillbirths | G9: 15
B10: Antepartum | G10: 13
B11: Intrapartum | G11: 2
B12: Livebirths | G12: 565
B13: Term births (≥37 completed weeks) | G13: 547
B14: Preterms (<37 completed weeks) | G14: 18
B15: Very Preterms (<34 completed weeks)
B16: Normal birthweight babies (≥ 2.5kg) | G16: 526
B17: Low birth weight babies (<2.5kg) | G17: 54
B18: Ver low birthweight babies (<1.5kg)
B19: Extremely low birthweight babies (<1.0kg)
B20: Neonatal deaths | G20: 15
B21: Early Neonatal Deaths (1-7 days) | G21: 13
B22: Late Neonatal Deaths (8-28 days) | G22: 2
B23: Maternal deaths | G23: 2

Sheet Jul20
A1: Home | B1: Month/Statistic | C1: Week 1 | D1: Week 2 | E1: Week 3 | F1: Week 4 | G1: Week 5 | H1: Recommendations
B2: Total Deliveries
B3: SVDs/NVDs
B4: Assisted
B5: Caesarean Sections
B6: Total Births
B7: Singletons
B8: Multiple
B9: Stillbirths
B10: Antepartum
B11: Intrapartum
B12: Livebirths
B13: Term births (≥37 completed weeks)
... B23: Maternal deaths

Sheet Aug20
A1: Home | B1: Month/Statistic | C1: Week 1 | D1: Week 2 | E1: Week 3 | F1: Week 4 | G1: Week 5 | H1: Recommendations
B2: Total Deliveries
B3: SVDs/NVDs
B4: Assisted
B5: Caesarean Sections
B6: Total Births
B7: Singletons
B8: Multiple
B9: Stillbirths
B10: Antepartum
B11: Intrapartum
B12: Livebirths
B13: Term births (≥37 completed weeks)
... B23: Maternal deaths

Sheet Sep20
A1: Home | B1: Month/Statistic | C1: Week 1 | D1: Week 2 | E1: Week 3 | F1: Week 4 | G1: Week 5 | H1: Recommendations
B2: Total Deliveries
B3: SVDs/NVDs
B4: Assisted
B5: Caesarean Sections
B6: Total Births
B7: Singletons
B8: Multiple
B9: Stillbirths
B10: Antepartum
B11: Intrapartum
B12: Livebirths
B13: Term births (≥37 completed weeks)
... B23: Maternal deaths

Sheet Oct20
A1: Home | B1: Month/Statistic | C1: Week 1 | D1: Week 2 | E1: Week 3 | F1: Week 4 | G1: Week 5 | H1: Recommendations
B2: Total Deliveries
B3: SVDs/NVDs
B4: Assisted
B5: Caesarean Sections
B6: Total Births
B7: Singletons
B8: Multiple
B9: Stillbirths
B10: Antepartum
B11: Intrapartum
B12: Livebirths
B13: Term births (≥37 completed weeks)
... B23: Maternal deaths

Sheet Nov20
A1: Home | B1: Month/Statistic | C1: Week 1 | D1: Week 2 | E1: Week 3 | F1: Week 4 | G1: Week 5 | H1: Recommendations
B2: Total Deliveries
B3: SVDs/NVDs
B4: Assisted
B5: Caesarean Sections
B6: Total Births
B7: Singletons
B8: Multiple
B9: Stillbirths
B10: Antepartum
B11: Intrapartum
B12: Livebirths
B13: Term births (≥37 completed weeks)
... B23: Maternal deaths

Sheet Dec20
A1: Home | B1: Month/Statistic | C1: Week 1 | D1: Week 2 | E1: Week 3 | F1: Week 4 | G1: Week 5 | H1: Recommendations
B2: Total Deliveries
B3: SVDs/NVDs
B4: Assisted
B5: Caesarean Sections
B6: Total Births
B7: Singletons
B8: Multiple
B9: Stillbirths
B10: Antepartum
B11: Intrapartum
B12: Livebirths
B13: Term births (≥37 completed weeks)
... B23: Maternal deaths

Sheet Jan
A1: Home | B1: Month/Statistic | C1: Week 1 | D1: Week 2 | E1: Week 3 | F1: Week 4 | G1: Week 5 | H1: Recommendations
B2: Total Deliveries | G2: 452
B3: SVDs/NVDs | G3: 368
B4: Assisted | G4: 1
B5: Caesarean Sections | G5: 83
B6: Total Births | G6: 447
B7: Singletons | G7: 429
B8: Multiple | G8: 10
B9: Stillbirths | G9: 8
B10: Antepartum | G10: 4
B11: Intrapartum | G11: 4
B12: Livebirths | G12: 439
B13: Term births (≥37 completed weeks)
B14: Preterms (<37 completed weeks)
B15: Very Preterms (<34 completed weeks)
B16: Normal birthweight babies (≥ 2.5kg) | G16: 410
B17: Low birth weight babies (<2.5kg) | G17: 29
B18: Ver low birthweight babies (<1.5kg)
B19: Extremely low birthweight babies (<1.0kg)
B20: Neonatal deaths | G20: 5
B21: Early Neonatal Deaths (1-7 days) | G21: 3
B22: Late Neonatal Deaths (8-28 days) | G22: 2
B23: Maternal deaths | G23: 0

Sheet Feb
A1: Home | B1: Month/Statistic | C1: Week 1 | D1: Week 2 | E1: Week 3 | F1: Week 4 | G1: Week 5 | H1: Recommendations
B2: Total Deliveries | G2: 377
B3: SVDs/NVDs | G3: 313
B4: Assisted | G4: 6
B5: Caesarean Sections | G5: 58
B6: Total Births | G6: 384
B7: Singletons | G7: 370
B8: Multiple | G8: 7
B9: Stillbirths | G9: 10
B10: Antepartum | G10: 6
B11: Intrapartum | G11: 4
B12: Livebirths | G12: 374
B13: Term births (≥37 completed weeks)
B14: Preterms (<37 completed weeks)
B15: Very Preterms (<34 completed weeks)
B16: Normal birthweight babies (≥ 2.5kg) | G16: 333
B17: Low birth weight babies (<2.5kg) | G17: 41
B18: Ver low birthweight babies (<1.5kg)
B19: Extremely low birthweight babies (<1.0kg)
B20: Neonatal deaths | G20: 7
B21: Early Neonatal Deaths (1-7 days) | G21: 6
B22: Late Neonatal Deaths (8-28 days) | G22: 1
B23: Maternal deaths | G23: 2

Sheet Mar
A1: Home | B1: Month/Statistic | C1: Week 1 | D1: Week 2 | E1: Week 3 | F1: Week 4 | G1: Week 5 | H1: Recommendations
B2: Total Deliveries | G2: 445
B3: SVDs/NVDs | G3: 357
B4: Assisted | G4: 1
B5: Caesarean Sections | G5: 87
B6: Total Births | G6: 450
B7: Singletons | G7: 438
B8: Multiple | G8: 7
B9: Stillbirths | G9: 11
B10: Antepartum | G10: 5
B11: Intrapartum | G11: 6
B12: Livebirths | G12: 441
B13: Term births (≥37 completed weeks)
B14: Preterms (<37 completed weeks)
B15: Very Preterms (<34 completed weeks)
B16: Normal birthweight babies (≥ 2.5kg) | G16: 353
B17: Low birth weight babies (<2.5kg) | G17: 63
B18: Ver low birthweight babies (<1.5kg)
B19: Extremely low birthweight babies (<1.0kg)
B20: Neonatal deaths | G20: 8
B21: Early Neonatal Deaths (1-7 days) | G21: 5
B22: Late Neonatal Deaths (8-28 days) | G22: 3
B23: Maternal deaths | G23: 2

Sheet Apr
A1: Home | B1: Month/Statistic | C1: Week 1 | D1: Week 2 | E1: Week 3 | F1: Week 4 | G1: Week 5 | H1: Recommendations
B2: Total Deliveries | G2: 411
B3: SVDs/NVDs | G3: 321
B4: Assisted | G4: 8
B5: Caesarean Sections | G5: 82
B6: Total Births | G6: 420
B7: Singletons | G7: 406
B8: Multiple | G8: 5
B9: Stillbirths | G9: 4
B10: Antepartum | G10: 2
B11: Intrapartum | G11: 2
B12: Livebirths | G12: 416
B13: Term births (≥37 completed weeks)
B14: Preterms (<37 completed weeks)
B15: Very Preterms (<34 completed weeks)
B16: Normal birthweight babies (≥ 2.5kg) | G16: 398
B17: Low birth weight babies (<2.5kg) | G17: 63
B18: Ver low birthweight babies (<1.5kg)
B19: Extremely low birthweight babies (<1.0kg)
B20: Neonatal deaths | G20: 10
B21: Early Neonatal Deaths (1-7 days) | G21: 7
B22: Late Neonatal Deaths (8-28 days) | G22: 3
B23: Maternal deaths | G23: 1

Sheet May
A1: Home | B1: Month/Statistic | C1: Week 1 | D1: Week 2 | E1: Week 3 | F1: Week 4 | G1: Week 5 | H1: Recommendations
B2: Total Deliveries | G2: 464
B3: SVDs/NVDs | G3: 376
B4: Assisted | G4: 4
B5: Caesarean Sections | G5: 84
B6: Total Births | G6: 470
B7: Singletons | G7: 461
B8: Multiple | G8: 3
B9: Stillbirths | G9: 9
B10: Antepartum | G10: 6
B11: Intrapartum | G11: 3
B12: Livebirths | G12: 461
B13: Term births (≥37 completed weeks)
B14: Preterms (<37 completed weeks)
B15: Very Preterms (<34 completed weeks)
B16: Normal birthweight babies (≥ 2.5kg) | G16: 410
B17: Low birth weight babies (<2.5kg) | G17: 51
B18: Ver low birthweight babies (<1.5kg)
B19: Extremely low birthweight babies (<1.0kg)
B20: Neonatal deaths | G20: 5
B21: Early Neonatal Deaths (1-7 days) | G21: 5
B22: Late Neonatal Deaths (8-28 days) | G22: 0
B23: Maternal deaths | G23: 3

Sheet Jun
A1: Home | B1: Month/Statistic | C1: Week 1 | D1: Week 2 | E1: Week 3 | F1: Week 4 | G1: Week 5/monthly total | H1: Recommendations
B2: Total Deliveries | G2: 428
B3: SVDs/NVDs | G3: 352
B4: Assisted | G4: 2
B5: Caesarean Sections | G5: 74
B6: Total Births | G6: 430
B7: Singletons | G7: 425
B8: Multiple | G8: 3
B9: Stillbirths | G9: 5
B10: Antepartum | G10: 2
B11: Intrapartum | G11: 3
B12: Livebirths | G12: 425
B13: Term births (≥37 completed weeks)
B14: Preterms (<37 completed weeks)
B15: Very Preterms (<34 completed weeks)
B16: Normal birthweight babies (≥ 2.5kg) | G16: 394
B17: Low birth weight babies (<2.5kg) | G17: 31
B18: Ver low birthweight babies (<1.5kg)
B19: Extremely low birthweight babies (<1.0kg)
B20: Neonatal deaths | G20: 5
B21: Early Neonatal Deaths (1-7 days) | G21: 3
B22: Late Neonatal Deaths (8-28 days) | G22: 2
B23: Maternal deaths | G23: 1

Sheet Jul
A1: Home | B1: Month/Statistic | C1: Week 1 | D1: Week 2 | E1: Week 3 | F1: Week 4 | G1: Week 5 | H1: Recommendations
B2: Total Deliveries | G2: 428
B3: SVDs/NVDs | G3: 342
B4: Assisted | G4: 7
B5: Caesarean Sections | G5: 79
B6: Total Births | G6: 434
B7: Singletons | G7: 422
B8: Multiple | G8: 12
B9: Stillbirths | G9: 6
B10: Antepartum | G10: 4
B11: Intrapartum | G11: 2
B12: Livebirths | G12: 428
B13: Term births (≥37 completed weeks) | G13: 407
B14: Preterms (<37 completed weeks) | G14: 21
B15: Very Preterms (<34 completed weeks)
B16: Normal birthweight babies (≥ 2.5kg) | G16: 375
B17: Low birth weight babies (<2.5kg) | G17: 53
B18: Ver low birthweight babies (<1.5kg)
B19: Extremely low birthweight babies (<1.0kg)
B20: Neonatal deaths | G20: 2
B21: Early Neonatal Deaths (1-7 days) | G21: 2
B22: Late Neonatal Deaths (8-28 days) | G22: 0
B23: Maternal deaths | G23: 1

Sheet Aug
A1: Home | B1: Month/Statistic | C1: Week 1 | D1: Week 2 | E1: Week 3 | F1: Week 4 | G1: Week 5 | H1: Recommendations
B2: Total Deliveries | C2: 104 | D2: 83 | E2: 109 | F2: 95
B3: SVDs/NVDs | C3: 85 | D3: 63 | E3: 93 | F3: 77
B4: Assisted | C4: 1 | D4: 0 | E4: 0 | F4: 3
B5: Caesarean Sections | C5: 18 | D5: 20 | E5: 16 | F5: 15
B6: Total Births | C6: 104 | D6: 83 | E6: 108 | F6: 95
B7: Singletons | C7: 104 | D7: 82 | E7: 106 | F7: 94
B8: Multiple | C8: 0 | D8: 1 | E8: 3 | F8: 1
B9: Stillbirths | C9: 3 | D9: 4 | E9: 1 | F9: 3
B10: Antepartum | C10: 3 | D10: 2 | E10: 0 | F10: 3
B11: Intrapartum | C11: 0 | D11: 2 | E11: 1 | F11: 0
B12: Livebirths | C12: 101 | D12: 79 | E12: 107 | F12: 92
B13: Term births (≥37 completed weeks)
B14: Preterms (<37 completed weeks)
B15: Very Preterms (<34 completed weeks)
B16: Normal birthweight babies (≥ 2.5kg) | C16: 87 | D16: 71 | E16: 98 | F16: 81
B17: Low birth weight babies (<2.5kg) | C17: 14 | D17: 13 | E17: 14 | F17: 13
B18: Ver low birthweight babies (<1.5kg) | C18: 1 | D18: 0 | E18: 0 | F18: 2
B19: Extremely low birthweight babies (<1.0kg) | C19: 0 | D19: 0 | E19: 0 | F19: 0
B20: Neonatal deaths | C20: 0 | D20: 1 | E20: 0 | F20: 1
B21: Early Neonatal Deaths (1-7 days) | C21: 0 | D21: 1 | E21: 0 | F21: 1
B22: Late Neonatal Deaths (8-28 days) | C22: 0 | D22: 0 | E22: 0 | F22: 0
B23: Maternal deaths | C23: 0 | D23: 1 | E23: 0 | F23: 1

Sheet Sep
A1: Home | B1: Month/Statistic | C1: Week 1 | D1: Week 2 | E1: Week 3 | F1: Week 4 | G1: Week 5 | H1: Recommendations
B2: Total Deliveries | G2: 467
B3: SVDs/NVDs | G3: 390
B4: Assisted | G4: 4
B5: Caesarean Sections | G5: 73
B6: Total Births | G6: 471
B7: Singletons | G7: 463
B8: Multiple | G8: 8
B9: Stillbirths | G9: 6
B10: Antepartum | G10: 3
B11: Intrapartum | G11: 3
B12: Livebirths | G12: 465
B13: Term births (≥37 completed weeks) | G13: 456
B14: Preterms (<37 completed weeks) | G14: 9
B15: Very Preterms (<34 completed weeks)
B16: Normal birthweight babies (≥ 2.5kg) | G16: 420
B17: Low birth weight babies (<2.5kg) | G17: 45
B18: Ver low birthweight babies (<1.5kg)
B19: Extremely low birthweight babies (<1.0kg)
B20: Neonatal deaths | G20: 1
B21: Early Neonatal Deaths (1-7 days) | G21: 1
B22: Late Neonatal Deaths (8-28 days)
B23: Maternal deaths | G23: 2

Sheet Oct
A1: Home | B1: Month/Statistic | C1: Week 1 | D1: Week 2 | E1: Week 3 | F1: Week 4 | G1: Week 5 | H1: Recommendations
B2: Total Deliveries | G2: 398
B3: SVDs/NVDs | G3: 339
B4: Assisted | G4: 3
B5: Caesarean Sections | G5: 56
B6: Total Births | G6: 404
B7: Singletons | G7: 394
B8: Multiple | G8: 10
B9: Stillbirths | G9: 6
B10: Antepartum | G10: 2
B11: Intrapartum | G11: 4
B12: Livebirths | G12: 381
B13: Term births (≥37 completed weeks) | G13: 364
B14: Preterms (<37 completed weeks) | G14: 17
B15: Very Preterms (<34 completed weeks)
B16: Normal birthweight babies (≥ 2.5kg) | G16: 362
B17: Low birth weight babies (<2.5kg) | G17: 19
B18: Ver low birthweight babies (<1.5kg)
B19: Extremely low birthweight babies (<1.0kg)
B20: Neonatal deaths | G20: 12
B21: Early Neonatal Deaths (1-7 days) | G21: 10
